<?xml version="1.0" ?>
<!-- This URDF was automatically created by SolidWorks to URDF Exporter! Originally created by Stephen Brawner (brawner@gmail.com) 
     Commit Version: 1.6.0-4-g7f85cfe  Build Version: 1.6.7995.38578
     For more information, please see http://wiki.ros.org/sw_urdf_exporter -->
<robot
  name="car" xmlns:xacro="http://ros.org/wiki/xacro">
  <link name="dummy_link"></link>
  <link
    name="base_link">
    <inertial>
      <origin
        xyz="0.00846276412694319 1.66533453693773E-16 -0.0258912541850395"
        rpy="0 0 0" />
      <mass
        value="24.808800425334" />
      <inertia
        ixx="0.535076472488201"
        ixy="3.50372688256584E-16"
        ixz="0.00114462079080184"
        iyy="1.90968810540177"
        iyz="-8.78958909355009E-19"
        izz="2.43338682295938" />
    </inertial>
    <visual>
      <origin
        xyz="0 0 0"
        rpy="0 0 0" />
      <geometry>
        <mesh
          filename="package://car/meshes/base_link.STL" />
      </geometry>
      <material
        name="">
        <color
          rgba="0.792156862745098 0.819607843137255 0.933333333333333 1" />
      </material>
    </visual>
    <collision>
      <origin
        xyz="0 0 0"
        rpy="0 0 0" />
      <geometry>
        <mesh
          filename="package://car/meshes/base_link.STL" />
      </geometry>
    </collision>
  </link>
  <joint name="dummy_joint" type="fixed">
    <origin rpy="0 0 0" xyz="0 0 0" />
    <parent link="dummy_link"/>
    <child link="base_link"/>
  </joint>
  <link
    name="left_hinge_front">
    <inertial>
      <origin
        xyz="-0.000120277605189179 -0.00350022524290422 0.0254"
        rpy="0 0 0" />
      <mass
        value="0.463471125188868" />
      <inertia
        ixx="0.00197270455567893"
        ixy="-6.11013623244949E-05"
        ixz="2.94273742643707E-20"
        iyy="0.000196679885199945"
        iyz="2.69019780391652E-19"
        izz="0.00197930187165054" />
    </inertial>
    <visual>
      <origin
        xyz="0 0 0"
        rpy="0 0 0" />
      <geometry>
        <mesh
          filename="package://car/meshes/left_hinge_front.STL" />
      </geometry>
      <material
        name="">
        <color
          rgba="0.792156862745098 0.819607843137255 0.933333333333333 1" />
      </material>
    </visual>
    <collision>
      <origin
        xyz="0 0 0"
        rpy="0 0 0" />
      <geometry>
        <mesh
          filename="package://car/meshes/left_hinge_front.STL" />
      </geometry>
    </collision>
  </link>
  <joint
    name="lefthingefront"
    type="revolute">
    <origin
      xyz="0.264799765141522 0.203199999999997 -0.1016"
      rpy="0 0 0.0386416997343079" />
    <parent
      link="base_link" />
    <child
      link="left_hinge_front" />
    <axis
      xyz="0 0 -1" />
    <limit
      lower="-3.14"
      upper="3.14"
      effort="0"
      velocity="0" />
  </joint>
  <link
    name="Left_wheel_front">
    <inertial>
      <origin
        xyz="-0.00306681650698584 -2.22044604925031E-16 0.0476632992826546"
        rpy="0 0 0" />
      <mass
        value="2.45721103449607" />
      <inertia
        ixx="0.00756591249272881"
        ixy="1.0283575538749E-18"
        ixz="-2.22681465401599E-05"
        iyy="0.00756581690842141"
        iyz="-1.88457462443331E-19"
        izz="0.0127535968260122" />
    </inertial>
    <visual>
      <origin
        xyz="0 0 0"
        rpy="0 0 0" />
      <geometry>
        <mesh
          filename="package://car/meshes/Left_wheel_front.STL" />
      </geometry>
      <material
        name="">
        <color
          rgba="0.792156862745098 0.819607843137255 0.933333333333333 1" />
      </material>
    </visual>
    <collision>
      <origin
        xyz="0 0 0"
        rpy="0 0 0" />
      <geometry>
        <mesh
          filename="package://car/meshes/Left_wheel_front.STL" />
      </geometry>
    </collision>
  </link>
  <joint
    name="leftwheelfront"
    type="continuous">
    <origin
      xyz="0.00514854787499253 0.0664863805378324 0.0253999999999999"
      rpy="-1.5707963267949 0 -0.0386416997343077" />
    <parent
      link="left_hinge_front" />
    <child
      link="Left_wheel_front" />
    <axis
      xyz="-0.00429238359232283 0 0.999990787679115" />
  </joint>
  <link
    name="right_hinge_front">
    <inertial>
      <origin
        xyz="-7.59833866305626E-05 0.00350146683239361 0.0254"
        rpy="0 0 0" />
      <mass
        value="0.463471125188869" />
      <inertia
        ixx="0.00197396624132431"
        ixy="3.86134664937877E-05"
        ixz="-1.4923300235631E-20"
        iyy="0.00019541819955457"
        iyz="-2.49636523660478E-19"
        izz="0.00197930187165054" />
    </inertial>
    <visual>
      <origin
        xyz="0 0 0"
        rpy="0 0 0" />
      <geometry>
        <mesh
          filename="package://car/meshes/right_hinge_front.STL" />
      </geometry>
      <material
        name="">
        <color
          rgba="0.792156862745098 0.819607843137255 0.933333333333333 1" />
      </material>
    </visual>
    <collision>
      <origin
        xyz="0 0 0"
        rpy="0 0 0" />
      <geometry>
        <mesh
          filename="package://car/meshes/right_hinge_front.STL" />
      </geometry>
    </collision>
  </link>
  <joint
    name="righthingefront"
    type="revolute">
    <origin
      xyz="0.264799765141519 -0.2032 -0.1016"
      rpy="0 0 0" />
    <parent
      link="base_link" />
    <child
      link="right_hinge_front" />
    <axis
      xyz="0 0 -1" />
    <limit
      lower="-3.14"
      upper="3.14"
      effort="0"
      velocity="0" />
  </joint>
  <link
    name="right_wheel_front">
    <inertial>
      <origin
        xyz="-0.00055358895971408 0 -0.0380130301891577"
        rpy="0 0 0" />
      <mass
        value="2.45721103449608" />
      <inertia
        ixx="0.00756825877729745"
        ixy="6.67749374612027E-19"
        ixz="-0.000112526214711238"
        iyy="0.00756581690842142"
        iyz="1.564637453037E-18"
        izz="0.0127512505414436" />
    </inertial>
    <visual>
      <origin
        xyz="0 0 0"
        rpy="0 0 0" />
      <geometry>
        <mesh
          filename="package://car/meshes/right_wheel_front.STL" />
      </geometry>
      <material
        name="">
        <color
          rgba="0.792156862745098 0.819607843137255 0.933333333333333 1" />
      </material>
    </visual>
    <collision>
      <origin
        xyz="0 0 0"
        rpy="0 0 0" />
      <geometry>
        <mesh
          filename="package://car/meshes/right_wheel_front.STL" />
      </geometry>
    </collision>
  </link>
  <joint
    name="rightwheelfront"
    type="continuous">
    <origin
      xyz="0.00303336595865666 -0.0762600668461264 0.0253999999999999"
      rpy="-1.5707963267949 0 0" />
    <parent
      link="right_hinge_front" />
    <child
      link="right_wheel_front" />
    <axis
      xyz="0.0216953368236426 0 -0.999764628480178" />
  </joint>
  <link
    name="left_hinge_back">
    <inertial>
      <origin
        xyz="-0.00608319327731177 0.0980977088280104 0.0132336134453782"
        rpy="0 0 0" />
      <mass
        value="0.463471125188868" />
      <inertia
        ixx="0.00197480417071053"
        ixy="1.17566600813061E-17"
        ixz="1.73229024851329E-22"
        iyy="0.000194580270168345"
        iyz="2.152503625571E-19"
        izz="0.00197930187165054" />
    </inertial>
    <visual>
      <origin
        xyz="0 0 0"
        rpy="0 0 0" />
      <geometry>
        <mesh
          filename="package://car/meshes/left_hinge_back.STL" />
      </geometry>
      <material
        name="">
        <color
          rgba="0.792156862745098 0.819607843137255 0.933333333333333 1" />
      </material>
    </visual>
    <collision>
      <origin
        xyz="0 0 0"
        rpy="0 0 0" />
      <geometry>
        <mesh
          filename="package://car/meshes/left_hinge_back.STL" />
      </geometry>
    </collision>
  </link>
  <joint
    name="lefthingeback"
    type="fixed">
    <origin
      xyz="-0.23711704158117 0.1016 -0.0894336134453781"
      rpy="0 0 0" />
    <parent
      link="base_link" />
    <child
      link="left_hinge_back" />
    <axis
      xyz="0 0 0" />
  </joint>
  <link
    name="left_wheel_back">
    <inertial>
      <origin
        xyz="5.55111512312578E-16 -2.22044604925031E-16 0.0381"
        rpy="0 0 0" />
      <mass
        value="2.45721103449607" />
      <inertia
        ixx="0.00756581690842141"
        ixy="-4.26086374897843E-19"
        ixz="-3.48296029793558E-17"
        iyy="0.00756581690842142"
        iyz="-2.88541231556167E-20"
        izz="0.0127536924103196" />
    </inertial>
    <visual>
      <origin
        xyz="0 0 0"
        rpy="0 0 0" />
      <geometry>
        <mesh
          filename="package://car/meshes/left_wheel_back.STL" />
      </geometry>
      <material
        name="">
        <color
          rgba="0.792156862745098 0.819607843137255 0.933333333333333 1" />
      </material>
    </visual>
    <collision>
      <origin
        xyz="0 0 0"
        rpy="0 0 0" />
      <geometry>
        <mesh
          filename="package://car/meshes/left_wheel_back.STL" />
      </geometry>
    </collision>
  </link>
  <joint
    name="leftwheelback"
    type="continuous">
    <origin
      xyz="-0.0060831932773121 0.177800000000009 0.0132336134453781"
      rpy="-1.5707963267949 0 0" />
    <parent
      link="left_hinge_back" />
    <child
      link="left_wheel_back" />
    <axis
      xyz="0 0 1" />
  </joint>
  <link
    name="right_hinge_back">
    <inertial>
      <origin
        xyz="0.00608319327731088 -0.0980977088280104 0.0132336134453781"
        rpy="0 0 0" />
      <mass
        value="0.463471125188869" />
      <inertia
        ixx="0.00197480417071053"
        ixy="-1.94981323063245E-19"
        ixz="-2.63421034547468E-22"
        iyy="0.000194580270168346"
        iyz="-2.57138713727107E-19"
        izz="0.00197930187165054" />
    </inertial>
    <visual>
      <origin
        xyz="0 0 0"
        rpy="0 0 0" />
      <geometry>
        <mesh
          filename="package://car/meshes/right_hinge_back.STL" />
      </geometry>
      <material
        name="">
        <color
          rgba="0.792156862745098 0.819607843137255 0.933333333333333 1" />
      </material>
    </visual>
    <collision>
      <origin
        xyz="0 0 0"
        rpy="0 0 0" />
      <geometry>
        <mesh
          filename="package://car/meshes/right_hinge_back.STL" />
      </geometry>
    </collision>
  </link>
  <joint
    name="righthingeback"
    type="fixed">
    <origin
      xyz="-0.249283428135792 -0.1016 -0.0894336134453781"
      rpy="0 0 0" />
    <parent
      link="base_link" />
    <child
      link="right_hinge_back" />
    <axis
      xyz="0 0 0" />
  </joint>
  <link
    name="right_wheel_back">
    <inertial>
      <origin
        xyz="0 0 -0.0381"
        rpy="0 0 0" />
      <mass
        value="2.45721103449608" />
      <inertia
        ixx="0.00756581690842141"
        ixy="3.07243844122817E-34"
        ixz="9.93953842907557E-19"
        iyy="0.00756581690842141"
        iyz="-1.71100024437671E-35"
        izz="0.0127536924103196" />
    </inertial>
    <visual>
      <origin
        xyz="0 0 0"
        rpy="0 0 0" />
      <geometry>
        <mesh
          filename="package://car/meshes/right_wheel_back.STL" />
      </geometry>
      <material
        name="">
        <color
          rgba="0.792156862745098 0.819607843137255 0.933333333333333 1" />
      </material>
    </visual>
    <collision>
      <origin
        xyz="0 0 0"
        rpy="0 0 0" />
      <geometry>
        <mesh
          filename="package://car/meshes/right_wheel_back.STL" />
      </geometry>
    </collision>
  </link>
  <joint
    name="rightwheelback"
    type="continuous">
    <origin
      xyz="0.00608319327731088 -0.1778 0.0132336134453781"
      rpy="-1.5707963267949 0 0" />
    <parent
      link="right_hinge_back" />
    <child
      link="right_wheel_back" />
    <axis
      xyz="0 0 -1" />
  </joint>
  <link
    name="lidar_link">
    <inertial>
      <origin
        xyz="0 -0.01 0.0508"
        rpy="0 0 0" />
      <mass
        value="0.823703678020892" />
      <inertia
        ixx="0.00123998155146124"
        ixy="2.12072395209952E-51"
        ixz="6.93649765430231E-35"
        iyy="0.00123998155146124"
        iyz="-4.10781393993733E-36"
        izz="0.00106284132982392" />
    </inertial>
    <visual>
      <origin
        xyz="0 0 0"
        rpy="0 0 0" />
      <geometry>
        <mesh
          filename="package://car/meshes/lidar_link.STL" />
      </geometry>
      <material
        name="">
        <color
          rgba="0.792156862745098 0.819607843137255 0.933333333333333 1" />
      </material>
    </visual>
    <collision>
      <origin
        xyz="0 0 0"
        rpy="0 0 0" />
      <geometry>
        <mesh
          filename="package://car/meshes/lidar_link.STL" />
      </geometry>
    </collision>
  </link>
  <joint
    name="lidar_joint"
    type="fixed">
    <origin
      xyz="0.379099765141519 -0.0100000000000001 0"
      rpy="0 0 3.14159265358979" />
    <parent
      link="base_link" />
    <child
      link="lidar_link" />
    <axis
      xyz="0 0 0" />
  </joint>
  <link
    name="arm_base">
    <inertial>
      <origin
        xyz="0.000193620942309958 0.000633314918081496 0.0101487298498182"
        rpy="0 0 0" />
      <mass
        value="0.03958568101" />
      <inertia
        ixx="0.00046191492409898"
        ixy="9.80242852222969E-06"
        ixz="-6.30155593572259E-07"
        iyy="0.000490973857408584"
        iyz="-2.06117999964601E-06"
        izz="0.000932332537192586" />
    </inertial>
    <visual>
      <origin
        xyz="0 0 0"
        rpy="0 0 0" />
      <geometry>
        <mesh
          filename="package://car/meshes/arm_base.STL" />
      </geometry>
      <material
        name="">
        <color
          rgba="0.752941176470588 0.752941176470588 0.752941176470588 1" />
      </material>
    </visual>
    <collision>
      <origin
        xyz="0 0 0"
        rpy="0 0 0" />
      <geometry>
        <mesh
          filename="package://car/meshes/arm_base.STL" />
      </geometry>
    </collision>
  </link>
  <joint
    name="arm_base_joint"
    type="fixed">
    <origin
      xyz="0.12583 0 -0.007"
      rpy="0 0 0" />
    <parent
      link="base_link" />
    <child
      link="arm_base" />
    <axis
      xyz="0 0 0" />
  </joint>
  <link
    name="link_1">
    <inertial>
      <origin
        xyz="2.40639276871679E-06 0.016438681190915 -0.00104225785399847"
        rpy="0 0 0" />
      <mass
        value="0.157302764148121" />
      <inertia
        ixx="0.00262070907732502"
        ixy="4.0497608638231E-07"
        ixz="-3.8882002524112E-08"
        iyy="0.00253798607030782"
        iyz="-0.000319319913855243"
        izz="0.00282982960040918" />
    </inertial>
    <visual>
      <origin
        xyz="0 0 0"
        rpy="0 0 0" />
      <geometry>
        <mesh
          filename="package://car/meshes/link_1.STL" />
      </geometry>
      <material
        name="">
        <color
          rgba="0.752941176470588 0.752941176470588 0.752941176470588 1" />
      </material>
    </visual>
    <collision>
      <origin
        xyz="0 0 0"
        rpy="0 0 0" />
      <geometry>
        <mesh
          filename="package://car/meshes/link_1.STL" />
      </geometry>
    </collision>
  </link>
  <joint
    name="link_joint_1"
    type="revolute">
    <origin
      xyz="0 0 0.087"
      rpy="0 0 3.1416" />
    <parent
      link="arm_base" />
    <child
      link="link_1" />
    <axis
      xyz="0 0 -1" />
    <limit
      lower="-3.14"
      upper="3.14"
      effort="0"
      velocity="0" />
  </joint>
  <link
    name="link_2">
    <inertial>
      <origin
        xyz="2.59275479419507E-08 -0.220745962139448 -0.00308657426217762"
        rpy="0 0 0" />
      <mass
        value="0.476559737275648" />
      <inertia
        ixx="0.0214353899877774"
        ixy="8.7500848387166E-07"
        ixz="-2.29374126881485E-07"
        iyy="0.00647593762561945"
        iyz="-4.03740667581547E-11"
        izz="0.0219277541062379" />
    </inertial>
    <visual>
      <origin
        xyz="0 0 0"
        rpy="0 0 0" />
      <geometry>
        <mesh
          filename="package://car/meshes/link_2.STL" />
      </geometry>
      <material
        name="">
        <color
          rgba="0.752941176470588 0.752941176470588 0.752941176470588 1" />
      </material>
    </visual>
    <collision>
      <origin
        xyz="0 0 0"
        rpy="0 0 0" />
      <geometry>
        <mesh
          filename="package://car/meshes/link_2.STL" />
      </geometry>
    </collision>
  </link>
  <joint
    name="link_joint_2"
    type="revolute">
    <origin
      xyz="7.1962E-05 0.135 0"
      rpy="-1.5708 0.010572 -0.00053305" />
    <parent
      link="link_1" />
    <child
      link="link_2" />
    <axis
      xyz="0 0 -1" />
    <limit
      lower="-3.14"
      upper="3.14"
      effort="0"
      velocity="0" />
  </joint>
  <link
    name="link_3">
    <inertial>
      <origin
        xyz="-0.184021304516838 -2.6723607111645E-06 -0.00404168059809995"
        rpy="0 0 0" />
      <mass
        value="0.261166310473817" />
      <inertia
        ixx="0.00212794989843684"
        ixy="3.96565963102743E-07"
        ixz="0.000112855905458283"
        iyy="0.0115421009233373"
        iyz="2.69310059727764E-07"
        izz="0.0116950875306116" />
    </inertial>
    <visual>
      <origin
        xyz="0 0 0"
        rpy="0 0 0" />
      <geometry>
        <mesh
          filename="package://car/meshes/link_3.STL" />
      </geometry>
      <material
        name="">
        <color
          rgba="0.752941176470588 0.752941176470588 0.752941176470588 1" />
      </material>
    </visual>
    <collision>
      <origin
        xyz="0 0 0"
        rpy="0 0 0" />
      <geometry>
        <mesh
          filename="package://car/meshes/link_3.STL" />
      </geometry>
    </collision>
  </link>
  <joint
    name="link_joint_3"
    type="revolute">
    <origin
      xyz="0 -0.425 -0.11995"
      rpy="3.1416 0 -3.1319" />
    <parent
      link="link_2" />
    <child
      link="link_3" />
    <axis
      xyz="0 0 1" />
    <limit
      lower="-3.14"
      upper="3.14"
      effort="0"
      velocity="0" />
  </joint>
  <link
    name="link_4">
    <inertial>
      <origin
        xyz="1.2327091388542E-05 -0.00245537172499566 -0.00409123831326841"
        rpy="0 0 0" />
      <mass
        value="0.054082941677261" />
      <inertia
        ixx="0.000387008009149904"
        ixy="-2.82465456251621E-07"
        ixz="4.1571166776992E-07"
        iyy="0.00042046733615558"
        iyz="4.27826591632895E-05"
        izz="0.000358368483914865" />
    </inertial>
    <visual>
      <origin
        xyz="0 0 0"
        rpy="0 0 0" />
      <geometry>
        <mesh
          filename="package://car/meshes/link_4.STL" />
      </geometry>
      <material
        name="">
        <color
          rgba="0.752941176470588 0.752941176470588 0.752941176470588 1" />
      </material>
    </visual>
    <collision>
      <origin
        xyz="0 0 0"
        rpy="0 0 0" />
      <geometry>
        <mesh
          filename="package://car/meshes/link_4.STL" />
      </geometry>
    </collision>
  </link>
  <joint
    name="link_joint_4"
    type="revolute">
    <origin
      xyz="-0.39225 0 -0.09492"
      rpy="3.1416 0 0.52654" />
    <parent
      link="link_3" />
    <child
      link="link_4" />
    <axis
      xyz="0 0 1" />
    <limit
      lower="-3.14"
      upper="3.14"
      effort="0"
      velocity="0" />
  </joint>
  <link
    name="link_5">
    <inertial>
      <origin
        xyz="1.36745470283861E-05 0.000938280863412189 -0.00442721949508784"
        rpy="0 0 0" />
      <mass
        value="0.0499793242094386" />
      <inertia
        ixx="0.00036221587813637"
        ixy="-2.81011469282609E-07"
        ixz="4.07551508710434E-07"
        iyy="0.000399431905229552"
        iyz="4.27790097540192E-05"
        izz="0.000333592424723564" />
    </inertial>
    <visual>
      <origin
        xyz="0 0 0"
        rpy="0 0 0" />
      <geometry>
        <mesh
          filename="package://car/meshes/link_5.STL" />
      </geometry>
      <material
        name="">
        <color
          rgba="0.752941176470588 0.752941176470588 0.752941176470588 1" />
      </material>
    </visual>
    <collision>
      <origin
        xyz="0 0 0"
        rpy="0 0 0" />
      <geometry>
        <mesh
          filename="package://car/meshes/link_5.STL" />
      </geometry>
    </collision>
  </link>
  <joint
    name="link_joint_5"
    type="revolute">
    <origin
      xyz="0 -0.09492 0"
      rpy="-1.5708 -1.4334 3.1416" />
    <parent
      link="link_4" />
    <child
      link="link_5" />
    <axis
      xyz="0 0 1" />
    <limit
      lower="-3.14"
      upper="3.14"
      effort="0"
      velocity="0" />
  </joint>
  <link
    name="link_6">
    <inertial>
      <origin
        xyz="-0.000102584931495286 -0.000149441288069152 -0.0115220918376515"
        rpy="0 0 0" />
      <mass
        value="0.013014641543707" />
      <inertia
        ixx="5.51992438321295E-05"
        ixy="3.25699349860647E-07"
        ixz="5.97598121341905E-08"
        iyy="5.54501301384627E-05"
        iyz="8.70555077500732E-08"
        izz="9.01432526904538E-05" />
    </inertial>
    <visual>
      <origin
        xyz="0 0 0"
        rpy="0 0 0" />
      <geometry>
        <mesh
          filename="package://car/meshes/link_6.STL" />
      </geometry>
      <material
        name="">
        <color
          rgba="0.752941176470588 0.752941176470588 0.752941176470588 1" />
      </material>
    </visual>
    <collision>
      <origin
        xyz="0 0 0"
        rpy="0 0 0" />
      <geometry>
        <mesh
          filename="package://car/meshes/link_6.STL" />
      </geometry>
    </collision>
  </link>
  <joint
    name="link_joint_6"
    type="revolute">
    <origin
      xyz="0 -0.07517 0"
      rpy="-1.5708 1.5705 -3.1416" />
    <parent
      link="link_5" />
    <child
      link="link_6" />
    <axis
      xyz="0 0 1" />
    <limit
      lower="-3.14"
      upper="3.14"
      effort="0"
      velocity="0" />
  </joint>


<ros2_control name="GazeboSystem" type="system">
 <hardware>
     <plugin>gazebo_ros2_control/GazeboSystem</plugin>
 </hardware>
 <!-- # Velocity Controllers -->

 <joint name="leftwheelfront">
     <command_interface name="velocity">
         <param name="min">-1000.0</param>
         <param name="max">1000.0</param>
     </command_interface>
     <state_interface name="position"/>
     <state_interface name="velocity"/>
 </joint>

  <joint name="rightwheelfront">
     <command_interface name="velocity">
         <param name="min">-1000.0</param>
         <param name="max">1000.0</param>
     </command_interface>
     <state_interface name="position"/>
     <state_interface name="velocity"/>
 </joint>

  <joint name="leftwheelback">
     <command_interface name="velocity">
         <param name="min">-1000.0</param>
         <param name="max">1000.0</param>
     </command_interface>
     <state_interface name="position"/>
     <state_interface name="velocity"/>
 </joint>

  <joint name="rightwheelback">
     <command_interface name="velocity">
         <param name="min">-1000.0</param>
         <param name="max">1000.0</param>
     </command_interface>
     <state_interface name="position"/>
     <state_interface name="velocity"/>
 </joint>
  <joint name="link_joint_1">
     <command_interface name="velocity">
         <param name="min">-3.14</param>
         <param name="max">3.14</param>
     </command_interface>
     <state_interface name="position"/>
     <state_interface name="velocity"/>
 </joint>

  <joint name="link_joint_2">
     <command_interface name="velocity">
         <param name="min">-3.14</param>
         <param name="max">3.14</param>
     </command_interface>
     <state_interface name="position"/>
     <state_interface name="velocity"/>
 </joint>

  <joint name="link_joint_3">
     <command_interface name="velocity">
         <param name="min">-3.14</param>
         <param name="max">3.14</param>
     </command_interface>
     <state_interface name="position"/>
     <state_interface name="velocity"/>
 </joint>

  <joint name="link_joint_4">
     <command_interface name="velocity">
         <param name="min">-3.14</param>
         <param name="max">3.14</param>
     </command_interface>
     <state_interface name="position"/>
     <state_interface name="velocity"/>
 </joint>

  <joint name="link_joint_5">
     <command_interface name="velocity">
         <param name="min">-3.14</param>
         <param name="max">3.14</param>
     </command_interface>
     <state_interface name="position"/>
     <state_interface name="velocity"/>
 </joint>

  <joint name="link_joint_6">
     <command_interface name="velocity">
         <param name="min">-3.14</param>
         <param name="max">3.14</param>
     </command_interface>
     <state_interface name="position"/>
     <state_interface name="velocity"/>
 </joint>

<!-- # Position Controller -->
 <joint name="lefthingefront">
     <command_interface name="position">
         <param name="min">-3.14</param>
         <param name="max">3.14</param>
     </command_interface>
     <state_interface name="position"/>
     <state_interface name="velocity"/>
 </joint>

  <joint name="righthingefront">
     <command_interface name="position">
         <param name="min">-3.14</param>
         <param name="max">3.14</param>
     </command_interface>
     <state_interface name="position"/>
     <state_interface name="velocity"/>
 </joint>

 <joint name="link_joint_1">
     <command_interface name="position">
         <param name="min">-3.14</param>
         <param name="max">3.14</param>
     </command_interface>
     <state_interface name="position"/>
     <state_interface name="velocity"/>
 </joint>

  <joint name="link_joint_2">
     <command_interface name="position">
         <param name="min">-3.14</param>
         <param name="max">3.14</param>
     </command_interface>
     <state_interface name="position"/>
     <state_interface name="velocity"/>
 </joint>

  <joint name="link_joint_3">
     <command_interface name="position">
         <param name="min">-3.14</param>
         <param name="max">3.14</param>
     </command_interface>
     <state_interface name="position"/>
     <state_interface name="velocity"/>
 </joint>

  <joint name="link_joint_4">
     <command_interface name="position">
         <param name="min">-3.14</param>
         <param name="max">3.14</param>
     </command_interface>
     <state_interface name="position"/>
     <state_interface name="velocity"/>
 </joint>

  <joint name="link_joint_5">
     <command_interface name="position">
         <param name="min">-3.14</param>
         <param name="max">3.14</param>
     </command_interface>
     <state_interface name="position"/>
     <state_interface name="velocity"/>
 </joint>

  <joint name="link_joint_6">
     <command_interface name="position">
         <param name="min">-3.14</param>
         <param name="max">3.14</param>
     </command_interface>
     <state_interface name="position"/>
     <state_interface name="velocity"/>
 </joint>
 </ros2_control>

 <gazebo>
    <plugin filename="libgazebo_ros2_control.so" name="gazebo_ros2_control">
        <parameters>$(find car)/config/control.yaml</parameters>
    </plugin>
 </gazebo>

 <xacro:macro name="body_color">
    <visual>
    <material>
        <ambient>0.8 0.558823529411765 0.1 1</ambient>
        <diffuse>0.8 0.558823529411765 0.1 1</diffuse>
        <specular>0.1 0.1 0.1 1</specular>
        <emissive>0 0 0 0</emissive>
    </material>
    </visual>
</xacro:macro>
<gazebo reference="base_link">
    <xacro:body_color />
</gazebo>

<xacro:macro name="lidar_color">
    <visual>
        <material>
            <ambient>0 0 0 1</ambient>
            <diffuse>0 0 0 1</diffuse>
            <specular>0 0 0 1</specular>
            <emissive>0 0 0 0</emissive>
        </material>
    </visual>
</xacro:macro>
<gazebo reference="lidar_link">
    <xacro:lidar_color />
</gazebo>

</robot>